<robot name="robot_6_dof">
  <!-- create link fixed to the "world" -->
  <link name="base_link">
    <visual>
      <origin rpy="0 0 0" xyz="0 0 0"/>
      <geometry>
        <mesh filename="package://robot_6_dof/meshes/visual/link_0.dae"/>
      </geometry>
    </visual>
    <collision>
      <origin rpy="0 0 0" xyz="0 0 0"/>
      <geometry>
        <mesh filename="package://robot_6_dof/meshes/collision/link_0.stl"/>
      </geometry>
    </collision>
    <inertial>
      <mass value="1"/>
      <inertia ixx="1.0" ixy="0.0" ixz="0.0" iyy="1.0" iyz="0.0" izz="1.0"/>
    </inertial>
  </link>
  <!-- additional links ... -->
  <link name="world"/>
  <link name="tool0"/>
  <joint name="base_joint" type="fixed">
    <parent link="world"/>
    <child link="base_link"/>
    <origin rpy="0 0 0" xyz="0 0 0"/>
    <axis xyz="0 0 1"/>
  </joint>
  <!-- joints - main serial chain -->
  <joint name="joint_1" type="revolute">
    <parent link="base_link"/>
    <child link="link_1"/>
    <origin rpy="0 0 0" xyz="0 0 0.061584"/>
    <axis xyz="0 0 1"/>
    <limit effort="1000.0" lower="-3.141592653589793" upper="3.141592653589793" velocity="2.5"/>
  </joint>
  <!-- additional joints ... -->
  <!-- ros2 control tag -->
  <ros2_control name="robot_6_dof" type="system">
    <hardware>
      <plugin>
        <!-- {Name_Space}/{Class_Name}-->
      </plugin>
    </hardware>
    <joint name="joint_1">
      <command_interface name="position">
        <param name="min">{-2*pi}</param>
        <param name="max">{2*pi}</param>
      </command_interface>
      <!-- additional command interfaces ... -->
      <state_interface name="position">
        <param name="initial_value">0.0</param>
      </state_interface>
      <!-- additional state interfaces ... -->
    </joint>
    <!-- additional joints ...-->
    <!-- additional hardware/sensors ...-->
  </ros2_control>
</robot>